---
title: エラー、 `throw` とその扱い
draft: true
---

:::caution
Rustacean の自分からすると、throw 文の存在意義が余りわからないので、分かる人追記してください。
:::

# なぜ存在するのか

`throw` は、「これ以上処理を続けられない状態」を処理するための言語レベルで用意された仕組みです。

これ以上処理を続けられない状態は、例えば「JSON がパースできない」「クライアントから送られてきた `body` の型が違う」「データベースと状態が競合する」や、「ネットワークが切断された」「メモリが足りなくなる」などが考えられます。

`throw` を使わないと、各関数中で明示的にエラーを確認して早期リターンするなどする必要があります。

`throw` を使うことで一時的に通常の実行から離脱できるので、それ以外の場所ではエラーのない関数と同じように書くことができます。

```ts
// throw を使わずにエラー処理をしようとした場合
function fn() {
  const result = anotherFn();
  if (result instanceof Error) return result
  return use(result);
}

// エラーが起きる場所で throw をする場合
function fn() {
  return use(anotherFn());
}
```

# `try ~ catch` 構文でエラー境界を定める

エラーを `throw` で投げることによってエラーを出しうる関数の扱いが簡単になりましたが、そのまま処理せずにいるとアプリケーション全体が落ちてしまいます。

`throw` したエラー (やエラー以外の値) は、 `try ~ catch` 構文で受け取ることができます。

```js
try {
  throw new Error("error!");
} catch (err) {
  console.log("caught", err);
}
```

# 実用的なエラーの扱い方

わからぬ
